<?xml version="1.0" encoding="UTF-8"?>
<testng-results skipped="0" failed="2" ignored="0" total="4" passed="2">
  <reporter-output>
  </reporter-output>
  <suite name="Suite" duration-ms="209845" started-at="2019-01-25T08:33:24Z" finished-at="2019-01-25T08:36:54Z">
    <groups>
    </groups>
    <test name="Test" duration-ms="209845" started-at="2019-01-25T08:33:24Z" finished-at="2019-01-25T08:36:54Z">
      <class name="restAPIFramework.api.test.TestCase">
        <test-method status="PASS" signature="Scenario_1()[pri:0, instance:restAPIFramework.api.test.TestCase@548b7f67]" name="Scenario_1" duration-ms="60691" started-at="2019-01-25T14:03:24Z" finished-at="2019-01-25T14:04:25Z">
          <reporter-output>
          </reporter-output>
        </test-method> <!-- Scenario_1 -->
        <test-method status="PASS" signature="Scenario_2()[pri:0, instance:restAPIFramework.api.test.TestCase@548b7f67]" name="Scenario_2" duration-ms="58735" started-at="2019-01-25T14:04:25Z" finished-at="2019-01-25T14:05:24Z">
          <reporter-output>
          </reporter-output>
        </test-method> <!-- Scenario_2 -->
        <test-method status="FAIL" signature="Scenario_3()[pri:0, instance:restAPIFramework.api.test.TestCase@548b7f67]" name="Scenario_3" duration-ms="45033" started-at="2019-01-25T14:05:24Z" finished-at="2019-01-25T14:06:09Z">
          <exception class="java.lang.AssertionError">
            <message>
              <![CDATA[expected [Completed] but found [Failure]]]>
            </message>
            <full-stacktrace>
              <![CDATA[java.lang.AssertionError: expected [Completed] but found [Failure]
	at org.testng.Assert.fail(Assert.java:94)
	at org.testng.Assert.failNotEquals(Assert.java:513)
	at org.testng.Assert.assertEqualsImpl(Assert.java:135)
	at org.testng.Assert.assertEquals(Assert.java:116)
	at org.testng.Assert.assertEquals(Assert.java:190)
	at org.testng.Assert.assertEquals(Assert.java:200)
	at restAPIFramework.api.test.TestCase.Scenario_3(TestCase.java:217)
	at sun.reflect.NativeMethodAccessorImpl.invoke0(Native Method)
	at sun.reflect.NativeMethodAccessorImpl.invoke(Unknown Source)
	at sun.reflect.DelegatingMethodAccessorImpl.invoke(Unknown Source)
	at java.lang.reflect.Method.invoke(Unknown Source)
	at org.testng.internal.MethodInvocationHelper.invokeMethod(MethodInvocationHelper.java:104)
	at org.testng.internal.Invoker.invokeMethod(Invoker.java:645)
	at org.testng.internal.Invoker.invokeTestMethod(Invoker.java:851)
	at org.testng.internal.Invoker.invokeTestMethods(Invoker.java:1177)
	at org.testng.internal.TestMethodWorker.invokeTestMethods(TestMethodWorker.java:129)
	at org.testng.internal.TestMethodWorker.run(TestMethodWorker.java:112)
	at org.testng.TestRunner.privateRun(TestRunner.java:756)
	at org.testng.TestRunner.run(TestRunner.java:610)
	at org.testng.SuiteRunner.runTest(SuiteRunner.java:387)
	at org.testng.SuiteRunner.runSequentially(SuiteRunner.java:382)
	at org.testng.SuiteRunner.privateRun(SuiteRunner.java:340)
	at org.testng.SuiteRunner.run(SuiteRunner.java:289)
	at org.testng.SuiteRunnerWorker.runSuite(SuiteRunnerWorker.java:52)
	at org.testng.SuiteRunnerWorker.run(SuiteRunnerWorker.java:86)
	at org.testng.TestNG.runSuitesSequentially(TestNG.java:1293)
	at org.testng.TestNG.runSuitesLocally(TestNG.java:1218)
	at org.testng.TestNG.runSuites(TestNG.java:1133)
	at org.testng.TestNG.run(TestNG.java:1104)
	at org.testng.remote.AbstractRemoteTestNG.run(AbstractRemoteTestNG.java:132)
	at org.testng.remote.RemoteTestNG.initAndRun(RemoteTestNG.java:230)
	at org.testng.remote.RemoteTestNG.main(RemoteTestNG.java:76)
]]>
            </full-stacktrace>
          </exception> <!-- java.lang.AssertionError -->
          <reporter-output>
          </reporter-output>
        </test-method> <!-- Scenario_3 -->
        <test-method status="FAIL" signature="Scenario_4()[pri:0, instance:restAPIFramework.api.test.TestCase@548b7f67]" name="Scenario_4" duration-ms="45349" started-at="2019-01-25T14:06:09Z" finished-at="2019-01-25T14:06:54Z">
          <exception class="java.lang.AssertionError">
            <message>
              <![CDATA[expected [Completed] but found [Failure]]]>
            </message>
            <full-stacktrace>
              <![CDATA[java.lang.AssertionError: expected [Completed] but found [Failure]
	at org.testng.Assert.fail(Assert.java:94)
	at org.testng.Assert.failNotEquals(Assert.java:513)
	at org.testng.Assert.assertEqualsImpl(Assert.java:135)
	at org.testng.Assert.assertEquals(Assert.java:116)
	at org.testng.Assert.assertEquals(Assert.java:190)
	at org.testng.Assert.assertEquals(Assert.java:200)
	at restAPIFramework.api.test.TestCase.Scenario_4(TestCase.java:285)
	at sun.reflect.NativeMethodAccessorImpl.invoke0(Native Method)
	at sun.reflect.NativeMethodAccessorImpl.invoke(Unknown Source)
	at sun.reflect.DelegatingMethodAccessorImpl.invoke(Unknown Source)
	at java.lang.reflect.Method.invoke(Unknown Source)
	at org.testng.internal.MethodInvocationHelper.invokeMethod(MethodInvocationHelper.java:104)
	at org.testng.internal.Invoker.invokeMethod(Invoker.java:645)
	at org.testng.internal.Invoker.invokeTestMethod(Invoker.java:851)
	at org.testng.internal.Invoker.invokeTestMethods(Invoker.java:1177)
	at org.testng.internal.TestMethodWorker.invokeTestMethods(TestMethodWorker.java:129)
	at org.testng.internal.TestMethodWorker.run(TestMethodWorker.java:112)
	at org.testng.TestRunner.privateRun(TestRunner.java:756)
	at org.testng.TestRunner.run(TestRunner.java:610)
	at org.testng.SuiteRunner.runTest(SuiteRunner.java:387)
	at org.testng.SuiteRunner.runSequentially(SuiteRunner.java:382)
	at org.testng.SuiteRunner.privateRun(SuiteRunner.java:340)
	at org.testng.SuiteRunner.run(SuiteRunner.java:289)
	at org.testng.SuiteRunnerWorker.runSuite(SuiteRunnerWorker.java:52)
	at org.testng.SuiteRunnerWorker.run(SuiteRunnerWorker.java:86)
	at org.testng.TestNG.runSuitesSequentially(TestNG.java:1293)
	at org.testng.TestNG.runSuitesLocally(TestNG.java:1218)
	at org.testng.TestNG.runSuites(TestNG.java:1133)
	at org.testng.TestNG.run(TestNG.java:1104)
	at org.testng.remote.AbstractRemoteTestNG.run(AbstractRemoteTestNG.java:132)
	at org.testng.remote.RemoteTestNG.initAndRun(RemoteTestNG.java:230)
	at org.testng.remote.RemoteTestNG.main(RemoteTestNG.java:76)
]]>
            </full-stacktrace>
          </exception> <!-- java.lang.AssertionError -->
          <reporter-output>
          </reporter-output>
        </test-method> <!-- Scenario_4 -->
      </class> <!-- restAPIFramework.api.test.TestCase -->
    </test> <!-- Test -->
  </suite> <!-- Suite -->
</testng-results>
